Traceback (most recent call last):
  File "scripts/GPT-4.py", line 110, in <module>
    main(args.perseus_dir, args.input_file, args.statistics)
  File "scripts/GPT-4.py", line 101, in main
    process_Perseus(perseus_dir, cluster_host_mapping, use_statistics)
  File "scripts/GPT-4.py", line 81, in process_Perseus
    aggregated_data = aggregate_data_for_day(perseus_dir, cluster, host_batch, day)
  File "scripts/GPT-4.py", line 40, in aggregate_data_for_day
    data = pd.read_csv(file_path)
  File "/home/cc/.local/lib/python3.8/site-packages/pandas/io/parsers/readers.py", line 912, in read_csv
    return _read(filepath_or_buffer, kwds)
  File "/home/cc/.local/lib/python3.8/site-packages/pandas/io/parsers/readers.py", line 577, in _read
    parser = TextFileReader(filepath_or_buffer, **kwds)
  File "/home/cc/.local/lib/python3.8/site-packages/pandas/io/parsers/readers.py", line 1407, in __init__
    self._engine = self._make_engine(f, self.engine)
  File "/home/cc/.local/lib/python3.8/site-packages/pandas/io/parsers/readers.py", line 1679, in _make_engine
    return mapping[engine](f, **self.options)
  File "/home/cc/.local/lib/python3.8/site-packages/pandas/io/parsers/c_parser_wrapper.py", line 93, in __init__
    self._reader = parsers.TextReader(src, **kwds)
  File "pandas/_libs/parsers.pyx", line 550, in pandas._libs.parsers.TextReader.__cinit__
  File "pandas/_libs/parsers.pyx", line 639, in pandas._libs.parsers.TextReader._get_header
  File "pandas/_libs/parsers.pyx", line 850, in pandas._libs.parsers.TextReader._tokenize_rows
  File "pandas/_libs/parsers.pyx", line 861, in pandas._libs.parsers.TextReader._check_tokenize_status
  File "pandas/_libs/parsers.pyx", line 2021, in pandas._libs.parsers.raise_parser_error
UnicodeDecodeError: 'utf-8' codec can't decode byte 0xb0 in position 45: invalid start byte
